[2025-02-02T12:49:28.951+0000] {local_task_job_runner.py:123} INFO - ::group::Pre task execution logs
[2025-02-02T12:49:28.967+0000] {taskinstance.py:2613} INFO - Dependencies all met for dep_context=non-requeueable deps ti=<TaskInstance: housekeeping_job.execute_job manual__2025-02-02T19:49:26+07:00 [queued]>
[2025-02-02T12:49:28.976+0000] {taskinstance.py:2613} INFO - Dependencies all met for dep_context=requeueable deps ti=<TaskInstance: housekeeping_job.execute_job manual__2025-02-02T19:49:26+07:00 [queued]>
[2025-02-02T12:49:28.977+0000] {taskinstance.py:2866} INFO - Starting attempt 1 of 2
[2025-02-02T12:49:28.991+0000] {taskinstance.py:2889} INFO - Executing <Task(PythonOperator): execute_job> on 2025-02-02 12:49:26+00:00
[2025-02-02T12:49:28.998+0000] {logging_mixin.py:190} WARNING - /home/***/.local/lib/python3.12/site-packages/***/task/task_runner/standard_task_runner.py:70 DeprecationWarning: This process (pid=1078) is multi-threaded, use of fork() may lead to deadlocks in the child.
[2025-02-02T12:49:28.999+0000] {standard_task_runner.py:72} INFO - Started process 1079 to run task
[2025-02-02T12:49:28.998+0000] {standard_task_runner.py:104} INFO - Running: ['***', 'tasks', 'run', 'housekeeping_job', 'execute_job', 'manual__2025-02-02T19:49:26+07:00', '--job-id', '322', '--raw', '--subdir', 'DAGS_FOLDER/housekeep.py', '--cfg-path', '/tmp/tmp736kl2l9']
[2025-02-02T12:49:29.000+0000] {standard_task_runner.py:105} INFO - Job 322: Subtask execute_job
[2025-02-02T12:49:29.042+0000] {task_command.py:467} INFO - Running <TaskInstance: housekeeping_job.execute_job manual__2025-02-02T19:49:26+07:00 [running]> on host f03ab8549fa5
[2025-02-02T12:49:29.126+0000] {taskinstance.py:3132} INFO - Exporting env vars: AIRFLOW_CTX_DAG_OWNER='***' AIRFLOW_CTX_DAG_ID='housekeeping_job' AIRFLOW_CTX_TASK_ID='execute_job' AIRFLOW_CTX_EXECUTION_DATE='2025-02-02T12:49:26+00:00' AIRFLOW_CTX_TRY_NUMBER='1' AIRFLOW_CTX_DAG_RUN_ID='manual__2025-02-02T19:49:26+07:00'
[2025-02-02T12:49:29.127+0000] {taskinstance.py:731} INFO - ::endgroup::
[2025-02-02T12:49:29.141+0000] {logging_mixin.py:190} INFO - An unexpected error occurred: fileno
[2025-02-02T12:49:29.142+0000] {taskinstance.py:3311} ERROR - Task failed with exception
Traceback (most recent call last):
  File "/home/airflow/.local/lib/python3.12/site-packages/airflow/models/taskinstance.py", line 767, in _execute_task
    result = _execute_callable(context=context, **execute_callable_kwargs)
             ^^^^^^^^^^^^^^^^^^^^^^^^^^^^^^^^^^^^^^^^^^^^^^^^^^^^^^^^^^^^^
  File "/home/airflow/.local/lib/python3.12/site-packages/airflow/models/taskinstance.py", line 733, in _execute_callable
    return ExecutionCallableRunner(
           ^^^^^^^^^^^^^^^^^^^^^^^^
  File "/home/airflow/.local/lib/python3.12/site-packages/airflow/utils/operator_helpers.py", line 252, in run
    return self.func(*args, **kwargs)
           ^^^^^^^^^^^^^^^^^^^^^^^^^^
  File "/home/airflow/.local/lib/python3.12/site-packages/airflow/models/baseoperator.py", line 422, in wrapper
    return func(self, *args, **kwargs)
           ^^^^^^^^^^^^^^^^^^^^^^^^^^^
  File "/home/airflow/.local/lib/python3.12/site-packages/airflow/operators/python.py", line 238, in execute
    return_value = self.execute_callable()
                   ^^^^^^^^^^^^^^^^^^^^^^^
  File "/home/airflow/.local/lib/python3.12/site-packages/airflow/operators/python.py", line 256, in execute_callable
    return runner.run(*self.op_args, **self.op_kwargs)
           ^^^^^^^^^^^^^^^^^^^^^^^^^^^^^^^^^^^^^^^^^^^
  File "/home/airflow/.local/lib/python3.12/site-packages/airflow/utils/operator_helpers.py", line 252, in run
    return self.func(*args, **kwargs)
           ^^^^^^^^^^^^^^^^^^^^^^^^^^
  File "/opt/airflow/dags/housekeep.py", line 38, in execute_python_job
    subprocess.run(["python", script_path, batchdate],stdout=sys.stdout, stderr=sys.stderr, check=True) # check=True raises exception on non-zero exit
    ^^^^^^^^^^^^^^^^^^^^^^^^^^^^^^^^^^^^^^^^^^^^^^^^^^^^^^^^^^^^^^^^^^^^^^^^^^^^^^^^^^^^^^^^^^^^^^^^^^^
  File "/usr/local/lib/python3.12/subprocess.py", line 548, in run
    with Popen(*popenargs, **kwargs) as process:
         ^^^^^^^^^^^^^^^^^^^^^^^^^^^
  File "/usr/local/lib/python3.12/subprocess.py", line 992, in __init__
    errread, errwrite) = self._get_handles(stdin, stdout, stderr)
                         ^^^^^^^^^^^^^^^^^^^^^^^^^^^^^^^^^^^^^^^^
  File "/usr/local/lib/python3.12/subprocess.py", line 1725, in _get_handles
    c2pwrite = stdout.fileno()
               ^^^^^^^^^^^^^^^
io.UnsupportedOperation: fileno
[2025-02-02T12:49:29.160+0000] {taskinstance.py:1225} INFO - Marking task as UP_FOR_RETRY. dag_id=housekeeping_job, task_id=execute_job, run_id=manual__2025-02-02T19:49:26+07:00, execution_date=20250202T124926, start_date=20250202T124928, end_date=20250202T124929
[2025-02-02T12:49:29.173+0000] {taskinstance.py:340} INFO - ::group::Post task execution logs
[2025-02-02T12:49:29.174+0000] {standard_task_runner.py:124} ERROR - Failed to execute job 322 for task execute_job (fileno; 1079)
Traceback (most recent call last):
  File "/home/airflow/.local/lib/python3.12/site-packages/airflow/task/task_runner/standard_task_runner.py", line 117, in _start_by_fork
    ret = args.func(args, dag=self.dag)
          ^^^^^^^^^^^^^^^^^^^^^^^^^^^^^
  File "/home/airflow/.local/lib/python3.12/site-packages/airflow/cli/cli_config.py", line 49, in command
    return func(*args, **kwargs)
           ^^^^^^^^^^^^^^^^^^^^^
  File "/home/airflow/.local/lib/python3.12/site-packages/airflow/utils/cli.py", line 116, in wrapper
    return f(*args, **kwargs)
           ^^^^^^^^^^^^^^^^^^
  File "/home/airflow/.local/lib/python3.12/site-packages/airflow/cli/commands/task_command.py", line 483, in task_run
    task_return_code = _run_task_by_selected_method(args, _dag, ti)
                       ^^^^^^^^^^^^^^^^^^^^^^^^^^^^^^^^^^^^^^^^^^^^
  File "/home/airflow/.local/lib/python3.12/site-packages/airflow/cli/commands/task_command.py", line 256, in _run_task_by_selected_method
    return _run_raw_task(args, ti)
           ^^^^^^^^^^^^^^^^^^^^^^^
  File "/home/airflow/.local/lib/python3.12/site-packages/airflow/cli/commands/task_command.py", line 341, in _run_raw_task
    return ti._run_raw_task(
           ^^^^^^^^^^^^^^^^^
  File "/home/airflow/.local/lib/python3.12/site-packages/airflow/utils/session.py", line 97, in wrapper
    return func(*args, session=session, **kwargs)
           ^^^^^^^^^^^^^^^^^^^^^^^^^^^^^^^^^^^^^^
  File "/home/airflow/.local/lib/python3.12/site-packages/airflow/models/taskinstance.py", line 3005, in _run_raw_task
    return _run_raw_task(
           ^^^^^^^^^^^^^^
  File "/home/airflow/.local/lib/python3.12/site-packages/airflow/models/taskinstance.py", line 273, in _run_raw_task
    TaskInstance._execute_task_with_callbacks(
  File "/home/airflow/.local/lib/python3.12/site-packages/airflow/models/taskinstance.py", line 3159, in _execute_task_with_callbacks
    result = self._execute_task(context, task_orig)
             ^^^^^^^^^^^^^^^^^^^^^^^^^^^^^^^^^^^^^^
  File "/home/airflow/.local/lib/python3.12/site-packages/airflow/models/taskinstance.py", line 3183, in _execute_task
    return _execute_task(self, context, task_orig)
           ^^^^^^^^^^^^^^^^^^^^^^^^^^^^^^^^^^^^^^^
  File "/home/airflow/.local/lib/python3.12/site-packages/airflow/models/taskinstance.py", line 767, in _execute_task
    result = _execute_callable(context=context, **execute_callable_kwargs)
             ^^^^^^^^^^^^^^^^^^^^^^^^^^^^^^^^^^^^^^^^^^^^^^^^^^^^^^^^^^^^^
  File "/home/airflow/.local/lib/python3.12/site-packages/airflow/models/taskinstance.py", line 733, in _execute_callable
    return ExecutionCallableRunner(
           ^^^^^^^^^^^^^^^^^^^^^^^^
  File "/home/airflow/.local/lib/python3.12/site-packages/airflow/utils/operator_helpers.py", line 252, in run
    return self.func(*args, **kwargs)
           ^^^^^^^^^^^^^^^^^^^^^^^^^^
  File "/home/airflow/.local/lib/python3.12/site-packages/airflow/models/baseoperator.py", line 422, in wrapper
    return func(self, *args, **kwargs)
           ^^^^^^^^^^^^^^^^^^^^^^^^^^^
  File "/home/airflow/.local/lib/python3.12/site-packages/airflow/operators/python.py", line 238, in execute
    return_value = self.execute_callable()
                   ^^^^^^^^^^^^^^^^^^^^^^^
  File "/home/airflow/.local/lib/python3.12/site-packages/airflow/operators/python.py", line 256, in execute_callable
    return runner.run(*self.op_args, **self.op_kwargs)
           ^^^^^^^^^^^^^^^^^^^^^^^^^^^^^^^^^^^^^^^^^^^
  File "/home/airflow/.local/lib/python3.12/site-packages/airflow/utils/operator_helpers.py", line 252, in run
    return self.func(*args, **kwargs)
           ^^^^^^^^^^^^^^^^^^^^^^^^^^
  File "/opt/airflow/dags/housekeep.py", line 38, in execute_python_job
    subprocess.run(["python", script_path, batchdate],stdout=sys.stdout, stderr=sys.stderr, check=True) # check=True raises exception on non-zero exit
    ^^^^^^^^^^^^^^^^^^^^^^^^^^^^^^^^^^^^^^^^^^^^^^^^^^^^^^^^^^^^^^^^^^^^^^^^^^^^^^^^^^^^^^^^^^^^^^^^^^^
  File "/usr/local/lib/python3.12/subprocess.py", line 548, in run
    with Popen(*popenargs, **kwargs) as process:
         ^^^^^^^^^^^^^^^^^^^^^^^^^^^
  File "/usr/local/lib/python3.12/subprocess.py", line 992, in __init__
    errread, errwrite) = self._get_handles(stdin, stdout, stderr)
                         ^^^^^^^^^^^^^^^^^^^^^^^^^^^^^^^^^^^^^^^^
  File "/usr/local/lib/python3.12/subprocess.py", line 1725, in _get_handles
    c2pwrite = stdout.fileno()
               ^^^^^^^^^^^^^^^
io.UnsupportedOperation: fileno
[2025-02-02T12:49:29.214+0000] {local_task_job_runner.py:266} INFO - Task exited with return code 1
[2025-02-02T12:49:29.234+0000] {taskinstance.py:3895} INFO - 0 downstream tasks scheduled from follow-on schedule check
[2025-02-02T12:49:29.235+0000] {local_task_job_runner.py:245} INFO - ::endgroup::
