[2025-07-22T07:07:17.407+0000] {local_task_job_runner.py:123} INFO - ::group::Pre task execution logs
[2025-07-22T07:07:17.421+0000] {taskinstance.py:2614} INFO - Dependencies all met for dep_context=non-requeueable deps ti=<TaskInstance: DataQualityOrchestration.FCT_LOAD.BATCH_ACT_VAL scheduled__2025-05-17T07:50:00+00:00 [queued]>
[2025-07-22T07:07:17.427+0000] {taskinstance.py:2614} INFO - Dependencies all met for dep_context=requeueable deps ti=<TaskInstance: DataQualityOrchestration.FCT_LOAD.BATCH_ACT_VAL scheduled__2025-05-17T07:50:00+00:00 [queued]>
[2025-07-22T07:07:17.428+0000] {taskinstance.py:2867} INFO - Starting attempt 2 of 2
[2025-07-22T07:07:17.440+0000] {taskinstance.py:2890} INFO - Executing <Task(BashOperator): FCT_LOAD.BATCH_ACT_VAL> on 2025-05-17 07:50:00+00:00
[2025-07-22T07:07:17.443+0000] {standard_task_runner.py:72} INFO - Started process 710 to run task
[2025-07-22T07:07:17.446+0000] {standard_task_runner.py:104} INFO - Running: ['***', 'tasks', 'run', 'DataQualityOrchestration', 'FCT_LOAD.BATCH_ACT_VAL', 'scheduled__2025-05-17T07:50:00+00:00', '--job-id', '454', '--raw', '--subdir', 'DAGS_FOLDER/dqc_***.py', '--cfg-path', '/tmp/tmpisjn8yea']
[2025-07-22T07:07:17.448+0000] {standard_task_runner.py:105} INFO - Job 454: Subtask FCT_LOAD.BATCH_ACT_VAL
[2025-07-22T07:07:17.490+0000] {task_command.py:467} INFO - Running <TaskInstance: DataQualityOrchestration.FCT_LOAD.BATCH_ACT_VAL scheduled__2025-05-17T07:50:00+00:00 [running]> on host 7ea0929a4780
[2025-07-22T07:07:17.562+0000] {taskinstance.py:3134} INFO - Exporting env vars: AIRFLOW_CTX_DAG_OWNER='***' AIRFLOW_CTX_DAG_ID='DataQualityOrchestration' AIRFLOW_CTX_TASK_ID='FCT_LOAD.BATCH_ACT_VAL' AIRFLOW_CTX_EXECUTION_DATE='2025-05-17T07:50:00+00:00' AIRFLOW_CTX_TRY_NUMBER='2' AIRFLOW_CTX_DAG_RUN_ID='scheduled__2025-05-17T07:50:00+00:00'
[2025-07-22T07:07:17.563+0000] {taskinstance.py:732} INFO - ::endgroup::
[2025-07-22T07:07:17.572+0000] {subprocess.py:78} INFO - Tmp dir root location: /tmp
[2025-07-22T07:07:17.573+0000] {subprocess.py:88} INFO - Running command: ['/usr/bin/bash', '-c', "set -e; docker exec spark-master /bin/bash -c '/mnt/apps/run_dm_spark.sh --batchname BATCH_ACT_VAL'"]
[2025-07-22T07:07:17.580+0000] {subprocess.py:99} INFO - Output:
[2025-07-22T07:07:17.652+0000] {subprocess.py:106} INFO - permission denied while trying to connect to the Docker daemon socket at unix:///var/run/docker.sock: Get "http://%2Fvar%2Frun%2Fdocker.sock/v1.47/containers/spark-master/json": dial unix /var/run/docker.sock: connect: permission denied
[2025-07-22T07:07:17.653+0000] {subprocess.py:110} INFO - Command exited with return code 1
[2025-07-22T07:07:17.662+0000] {taskinstance.py:3313} ERROR - Task failed with exception
Traceback (most recent call last):
  File "/home/airflow/.local/lib/python3.8/site-packages/airflow/models/taskinstance.py", line 768, in _execute_task
    result = _execute_callable(context=context, **execute_callable_kwargs)
  File "/home/airflow/.local/lib/python3.8/site-packages/airflow/models/taskinstance.py", line 734, in _execute_callable
    return ExecutionCallableRunner(
  File "/home/airflow/.local/lib/python3.8/site-packages/airflow/utils/operator_helpers.py", line 252, in run
    return self.func(*args, **kwargs)
  File "/home/airflow/.local/lib/python3.8/site-packages/airflow/models/baseoperator.py", line 424, in wrapper
    return func(self, *args, **kwargs)
  File "/home/airflow/.local/lib/python3.8/site-packages/airflow/operators/bash.py", line 276, in execute
    raise AirflowException(
airflow.exceptions.AirflowException: Bash command failed. The command returned a non-zero exit code 1.
[2025-07-22T07:07:17.666+0000] {taskinstance.py:1226} INFO - Marking task as FAILED. dag_id=DataQualityOrchestration, task_id=FCT_LOAD.BATCH_ACT_VAL, run_id=scheduled__2025-05-17T07:50:00+00:00, execution_date=20250517T075000, start_date=20250722T070717, end_date=20250722T070717
[2025-07-22T07:07:17.689+0000] {taskinstance.py:341} INFO - ::group::Post task execution logs
[2025-07-22T07:07:17.690+0000] {standard_task_runner.py:124} ERROR - Failed to execute job 454 for task FCT_LOAD.BATCH_ACT_VAL (Bash command failed. The command returned a non-zero exit code 1.; 710)
Traceback (most recent call last):
  File "/home/airflow/.local/lib/python3.8/site-packages/airflow/task/task_runner/standard_task_runner.py", line 117, in _start_by_fork
    ret = args.func(args, dag=self.dag)
  File "/home/airflow/.local/lib/python3.8/site-packages/airflow/cli/cli_config.py", line 49, in command
    return func(*args, **kwargs)
  File "/home/airflow/.local/lib/python3.8/site-packages/airflow/utils/cli.py", line 116, in wrapper
    return f(*args, **kwargs)
  File "/home/airflow/.local/lib/python3.8/site-packages/airflow/cli/commands/task_command.py", line 483, in task_run
    task_return_code = _run_task_by_selected_method(args, _dag, ti)
  File "/home/airflow/.local/lib/python3.8/site-packages/airflow/cli/commands/task_command.py", line 256, in _run_task_by_selected_method
    return _run_raw_task(args, ti)
  File "/home/airflow/.local/lib/python3.8/site-packages/airflow/cli/commands/task_command.py", line 341, in _run_raw_task
    return ti._run_raw_task(
  File "/home/airflow/.local/lib/python3.8/site-packages/airflow/utils/session.py", line 97, in wrapper
    return func(*args, session=session, **kwargs)
  File "/home/airflow/.local/lib/python3.8/site-packages/airflow/models/taskinstance.py", line 3006, in _run_raw_task
    return _run_raw_task(
  File "/home/airflow/.local/lib/python3.8/site-packages/airflow/models/taskinstance.py", line 274, in _run_raw_task
    TaskInstance._execute_task_with_callbacks(
  File "/home/airflow/.local/lib/python3.8/site-packages/airflow/models/taskinstance.py", line 3161, in _execute_task_with_callbacks
    result = self._execute_task(context, task_orig)
  File "/home/airflow/.local/lib/python3.8/site-packages/airflow/models/taskinstance.py", line 3185, in _execute_task
    return _execute_task(self, context, task_orig)
  File "/home/airflow/.local/lib/python3.8/site-packages/airflow/models/taskinstance.py", line 768, in _execute_task
    result = _execute_callable(context=context, **execute_callable_kwargs)
  File "/home/airflow/.local/lib/python3.8/site-packages/airflow/models/taskinstance.py", line 734, in _execute_callable
    return ExecutionCallableRunner(
  File "/home/airflow/.local/lib/python3.8/site-packages/airflow/utils/operator_helpers.py", line 252, in run
    return self.func(*args, **kwargs)
  File "/home/airflow/.local/lib/python3.8/site-packages/airflow/models/baseoperator.py", line 424, in wrapper
    return func(self, *args, **kwargs)
  File "/home/airflow/.local/lib/python3.8/site-packages/airflow/operators/bash.py", line 276, in execute
    raise AirflowException(
airflow.exceptions.AirflowException: Bash command failed. The command returned a non-zero exit code 1.
[2025-07-22T07:07:17.699+0000] {local_task_job_runner.py:266} INFO - Task exited with return code 1
[2025-07-22T07:07:17.712+0000] {taskinstance.py:3901} INFO - 0 downstream tasks scheduled from follow-on schedule check
[2025-07-22T07:07:17.714+0000] {local_task_job_runner.py:245} INFO - ::endgroup::
