[2025-04-18T08:18:24.570+0000] {local_task_job_runner.py:123} INFO - ::group::Pre task execution logs
[2025-04-18T08:18:24.584+0000] {taskinstance.py:2614} INFO - Dependencies all met for dep_context=non-requeueable deps ti=<TaskInstance: ssh_to_host_with_paramiko.execute_remote_script_on_host manual__2025-04-18T08:16:12.616522+00:00 [queued]>
[2025-04-18T08:18:24.591+0000] {taskinstance.py:2614} INFO - Dependencies all met for dep_context=requeueable deps ti=<TaskInstance: ssh_to_host_with_paramiko.execute_remote_script_on_host manual__2025-04-18T08:16:12.616522+00:00 [queued]>
[2025-04-18T08:18:24.591+0000] {taskinstance.py:2867} INFO - Starting attempt 2 of 2
[2025-04-18T08:18:24.603+0000] {taskinstance.py:2890} INFO - Executing <Task(PythonOperator): execute_remote_script_on_host> on 2025-04-18 08:16:12.616522+00:00
[2025-04-18T08:18:24.607+0000] {standard_task_runner.py:72} INFO - Started process 418 to run task
[2025-04-18T08:18:24.610+0000] {standard_task_runner.py:104} INFO - Running: ['***', 'tasks', 'run', 'ssh_to_host_with_paramiko', 'execute_remote_script_on_host', 'manual__2025-04-18T08:16:12.616522+00:00', '--job-id', '331', '--raw', '--subdir', 'DAGS_FOLDER/executeremote.py', '--cfg-path', '/tmp/tmp5yg9eraa']
[2025-04-18T08:18:24.612+0000] {standard_task_runner.py:105} INFO - Job 331: Subtask execute_remote_script_on_host
[2025-04-18T08:18:24.656+0000] {task_command.py:467} INFO - Running <TaskInstance: ssh_to_host_with_paramiko.execute_remote_script_on_host manual__2025-04-18T08:16:12.616522+00:00 [running]> on host 539fb9046bc5
[2025-04-18T08:18:24.724+0000] {taskinstance.py:3134} INFO - Exporting env vars: AIRFLOW_CTX_DAG_OWNER='***' AIRFLOW_CTX_DAG_ID='ssh_to_host_with_paramiko' AIRFLOW_CTX_TASK_ID='execute_remote_script_on_host' AIRFLOW_CTX_EXECUTION_DATE='2025-04-18T08:16:12.616522+00:00' AIRFLOW_CTX_TRY_NUMBER='2' AIRFLOW_CTX_DAG_RUN_ID='manual__2025-04-18T08:16:12.616522+00:00'
[2025-04-18T08:18:24.725+0000] {taskinstance.py:732} INFO - ::endgroup::
[2025-04-18T08:18:24.771+0000] {transport.py:1944} INFO - Connected (version 2.0, client OpenSSH_9.6p1)
[2025-04-18T08:18:24.791+0000] {transport.py:1944} INFO - Authentication (publickey) failed.
[2025-04-18T08:18:24.834+0000] {transport.py:1944} INFO - Authentication (publickey) failed.
[2025-04-18T08:18:24.835+0000] {taskinstance.py:3313} ERROR - Task failed with exception
Traceback (most recent call last):
  File "/opt/airflow/dags/executeremote.py", line 33, in execute_remote_script_with_paramiko
    ssh_client.connect(hostname=REMOTE_HOST, username=REMOTE_USER, pkey=private_key)
  File "/home/airflow/.local/lib/python3.8/site-packages/paramiko/client.py", line 485, in connect
    self._auth(
  File "/home/airflow/.local/lib/python3.8/site-packages/paramiko/client.py", line 818, in _auth
    raise saved_exception
  File "/home/airflow/.local/lib/python3.8/site-packages/paramiko/client.py", line 794, in _auth
    self._transport.auth_publickey(username, key)
  File "/home/airflow/.local/lib/python3.8/site-packages/paramiko/transport.py", line 1709, in auth_publickey
    return self.auth_handler.wait_for_response(my_event)
  File "/home/airflow/.local/lib/python3.8/site-packages/paramiko/auth_handler.py", line 263, in wait_for_response
    raise e
paramiko.ssh_exception.AuthenticationException: Authentication failed.

During handling of the above exception, another exception occurred:

Traceback (most recent call last):
  File "/home/airflow/.local/lib/python3.8/site-packages/airflow/models/taskinstance.py", line 768, in _execute_task
    result = _execute_callable(context=context, **execute_callable_kwargs)
  File "/home/airflow/.local/lib/python3.8/site-packages/airflow/models/taskinstance.py", line 734, in _execute_callable
    return ExecutionCallableRunner(
  File "/home/airflow/.local/lib/python3.8/site-packages/airflow/utils/operator_helpers.py", line 252, in run
    return self.func(*args, **kwargs)
  File "/home/airflow/.local/lib/python3.8/site-packages/airflow/models/baseoperator.py", line 424, in wrapper
    return func(self, *args, **kwargs)
  File "/home/airflow/.local/lib/python3.8/site-packages/airflow/operators/python.py", line 238, in execute
    return_value = self.execute_callable()
  File "/home/airflow/.local/lib/python3.8/site-packages/airflow/operators/python.py", line 256, in execute_callable
    return runner.run(*self.op_args, **self.op_kwargs)
  File "/home/airflow/.local/lib/python3.8/site-packages/airflow/utils/operator_helpers.py", line 252, in run
    return self.func(*args, **kwargs)
  File "/opt/airflow/dags/executeremote.py", line 49, in execute_remote_script_with_paramiko
    raise Exception(f"Error executing remote command: {e}")
Exception: Error executing remote command: Authentication failed.
[2025-04-18T08:18:24.847+0000] {taskinstance.py:1226} INFO - Marking task as FAILED. dag_id=ssh_to_host_with_paramiko, task_id=execute_remote_script_on_host, run_id=manual__2025-04-18T08:16:12.616522+00:00, execution_date=20250418T081612, start_date=20250418T081824, end_date=20250418T081824
[2025-04-18T08:18:24.871+0000] {taskinstance.py:341} INFO - ::group::Post task execution logs
[2025-04-18T08:18:24.871+0000] {standard_task_runner.py:124} ERROR - Failed to execute job 331 for task execute_remote_script_on_host (Error executing remote command: Authentication failed.; 418)
Traceback (most recent call last):
  File "/opt/airflow/dags/executeremote.py", line 33, in execute_remote_script_with_paramiko
    ssh_client.connect(hostname=REMOTE_HOST, username=REMOTE_USER, pkey=private_key)
  File "/home/airflow/.local/lib/python3.8/site-packages/paramiko/client.py", line 485, in connect
    self._auth(
  File "/home/airflow/.local/lib/python3.8/site-packages/paramiko/client.py", line 818, in _auth
    raise saved_exception
  File "/home/airflow/.local/lib/python3.8/site-packages/paramiko/client.py", line 794, in _auth
    self._transport.auth_publickey(username, key)
  File "/home/airflow/.local/lib/python3.8/site-packages/paramiko/transport.py", line 1709, in auth_publickey
    return self.auth_handler.wait_for_response(my_event)
  File "/home/airflow/.local/lib/python3.8/site-packages/paramiko/auth_handler.py", line 263, in wait_for_response
    raise e
paramiko.ssh_exception.AuthenticationException: Authentication failed.

During handling of the above exception, another exception occurred:

Traceback (most recent call last):
  File "/home/airflow/.local/lib/python3.8/site-packages/airflow/task/task_runner/standard_task_runner.py", line 117, in _start_by_fork
    ret = args.func(args, dag=self.dag)
  File "/home/airflow/.local/lib/python3.8/site-packages/airflow/cli/cli_config.py", line 49, in command
    return func(*args, **kwargs)
  File "/home/airflow/.local/lib/python3.8/site-packages/airflow/utils/cli.py", line 116, in wrapper
    return f(*args, **kwargs)
  File "/home/airflow/.local/lib/python3.8/site-packages/airflow/cli/commands/task_command.py", line 483, in task_run
    task_return_code = _run_task_by_selected_method(args, _dag, ti)
  File "/home/airflow/.local/lib/python3.8/site-packages/airflow/cli/commands/task_command.py", line 256, in _run_task_by_selected_method
    return _run_raw_task(args, ti)
  File "/home/airflow/.local/lib/python3.8/site-packages/airflow/cli/commands/task_command.py", line 341, in _run_raw_task
    return ti._run_raw_task(
  File "/home/airflow/.local/lib/python3.8/site-packages/airflow/utils/session.py", line 97, in wrapper
    return func(*args, session=session, **kwargs)
  File "/home/airflow/.local/lib/python3.8/site-packages/airflow/models/taskinstance.py", line 3006, in _run_raw_task
    return _run_raw_task(
  File "/home/airflow/.local/lib/python3.8/site-packages/airflow/models/taskinstance.py", line 274, in _run_raw_task
    TaskInstance._execute_task_with_callbacks(
  File "/home/airflow/.local/lib/python3.8/site-packages/airflow/models/taskinstance.py", line 3161, in _execute_task_with_callbacks
    result = self._execute_task(context, task_orig)
  File "/home/airflow/.local/lib/python3.8/site-packages/airflow/models/taskinstance.py", line 3185, in _execute_task
    return _execute_task(self, context, task_orig)
  File "/home/airflow/.local/lib/python3.8/site-packages/airflow/models/taskinstance.py", line 768, in _execute_task
    result = _execute_callable(context=context, **execute_callable_kwargs)
  File "/home/airflow/.local/lib/python3.8/site-packages/airflow/models/taskinstance.py", line 734, in _execute_callable
    return ExecutionCallableRunner(
  File "/home/airflow/.local/lib/python3.8/site-packages/airflow/utils/operator_helpers.py", line 252, in run
    return self.func(*args, **kwargs)
  File "/home/airflow/.local/lib/python3.8/site-packages/airflow/models/baseoperator.py", line 424, in wrapper
    return func(self, *args, **kwargs)
  File "/home/airflow/.local/lib/python3.8/site-packages/airflow/operators/python.py", line 238, in execute
    return_value = self.execute_callable()
  File "/home/airflow/.local/lib/python3.8/site-packages/airflow/operators/python.py", line 256, in execute_callable
    return runner.run(*self.op_args, **self.op_kwargs)
  File "/home/airflow/.local/lib/python3.8/site-packages/airflow/utils/operator_helpers.py", line 252, in run
    return self.func(*args, **kwargs)
  File "/opt/airflow/dags/executeremote.py", line 49, in execute_remote_script_with_paramiko
    raise Exception(f"Error executing remote command: {e}")
Exception: Error executing remote command: Authentication failed.
[2025-04-18T08:18:24.904+0000] {local_task_job_runner.py:266} INFO - Task exited with return code 1
[2025-04-18T08:18:24.924+0000] {taskinstance.py:3901} INFO - 0 downstream tasks scheduled from follow-on schedule check
[2025-04-18T08:18:24.926+0000] {local_task_job_runner.py:245} INFO - ::endgroup::
