[2025-04-18T08:04:52.923+0000] {local_task_job_runner.py:123} INFO - ::group::Pre task execution logs
[2025-04-18T08:04:52.940+0000] {taskinstance.py:2614} INFO - Dependencies all met for dep_context=non-requeueable deps ti=<TaskInstance: ssh_to_host_from_config.execute_remote_script_on_host manual__2025-04-18T08:04:52.210566+00:00 [queued]>
[2025-04-18T08:04:52.953+0000] {taskinstance.py:2614} INFO - Dependencies all met for dep_context=requeueable deps ti=<TaskInstance: ssh_to_host_from_config.execute_remote_script_on_host manual__2025-04-18T08:04:52.210566+00:00 [queued]>
[2025-04-18T08:04:52.954+0000] {taskinstance.py:2867} INFO - Starting attempt 1 of 1
[2025-04-18T08:04:53.074+0000] {taskinstance.py:2890} INFO - Executing <Task(BashOperator): execute_remote_script_on_host> on 2025-04-18 08:04:52.210566+00:00
[2025-04-18T08:04:53.079+0000] {standard_task_runner.py:72} INFO - Started process 204 to run task
[2025-04-18T08:04:53.083+0000] {standard_task_runner.py:104} INFO - Running: ['***', 'tasks', 'run', 'ssh_to_host_from_config', 'execute_remote_script_on_host', 'manual__2025-04-18T08:04:52.210566+00:00', '--job-id', '327', '--raw', '--subdir', 'DAGS_FOLDER/executeremote.py', '--cfg-path', '/tmp/tmpnw95_o6a']
[2025-04-18T08:04:53.085+0000] {standard_task_runner.py:105} INFO - Job 327: Subtask execute_remote_script_on_host
[2025-04-18T08:04:53.132+0000] {task_command.py:467} INFO - Running <TaskInstance: ssh_to_host_from_config.execute_remote_script_on_host manual__2025-04-18T08:04:52.210566+00:00 [running]> on host 322893c3014f
[2025-04-18T08:04:53.206+0000] {taskinstance.py:3134} INFO - Exporting env vars: AIRFLOW_CTX_DAG_OWNER='***' AIRFLOW_CTX_DAG_ID='ssh_to_host_from_config' AIRFLOW_CTX_TASK_ID='execute_remote_script_on_host' AIRFLOW_CTX_EXECUTION_DATE='2025-04-18T08:04:52.210566+00:00' AIRFLOW_CTX_TRY_NUMBER='1' AIRFLOW_CTX_DAG_RUN_ID='manual__2025-04-18T08:04:52.210566+00:00'
[2025-04-18T08:04:53.207+0000] {taskinstance.py:732} INFO - ::endgroup::
[2025-04-18T08:04:53.238+0000] {subprocess.py:78} INFO - Tmp dir root location: /tmp
[2025-04-18T08:04:53.239+0000] {subprocess.py:88} INFO - Running command: ['/usr/bin/bash', '-c', 'ssh -i /home/***/.ssh/id_rsa -o StrictHostKeyChecking=no agam@172.27.23.224 "bash /mnt/e/Repo/Spark-Bitnami/***-data/sync.sh"']
[2025-04-18T08:04:53.245+0000] {subprocess.py:99} INFO - Output:
[2025-04-18T08:04:53.340+0000] {subprocess.py:106} INFO - Warning: Permanently added '172.27.23.224' (ED25519) to the list of known hosts.
[2025-04-18T08:04:53.367+0000] {subprocess.py:106} INFO - @@@@@@@@@@@@@@@@@@@@@@@@@@@@@@@@@@@@@@@@@@@@@@@@@@@@@@@@@@@
[2025-04-18T08:04:53.367+0000] {subprocess.py:106} INFO - @         WARNING: UNPROTECTED PRIVATE KEY FILE!          @
[2025-04-18T08:04:53.368+0000] {subprocess.py:106} INFO - @@@@@@@@@@@@@@@@@@@@@@@@@@@@@@@@@@@@@@@@@@@@@@@@@@@@@@@@@@@
[2025-04-18T08:04:53.368+0000] {subprocess.py:106} INFO - Permissions 0777 for '/home/***/.ssh/id_rsa' are too open.
[2025-04-18T08:04:53.368+0000] {subprocess.py:106} INFO - It is required that your private key files are NOT accessible by others.
[2025-04-18T08:04:53.369+0000] {subprocess.py:106} INFO - This private key will be ignored.
[2025-04-18T08:04:53.369+0000] {subprocess.py:106} INFO - Load key "/home/***/.ssh/id_rsa": bad permissions
[2025-04-18T08:04:53.374+0000] {subprocess.py:106} INFO - Permission denied, please try again.
[2025-04-18T08:04:53.381+0000] {subprocess.py:106} INFO - Permission denied, please try again.
[2025-04-18T08:04:53.388+0000] {subprocess.py:106} INFO - agam@172.27.23.224: Permission denied (publickey,password).
[2025-04-18T08:04:53.389+0000] {subprocess.py:110} INFO - Command exited with return code 255
[2025-04-18T08:04:53.400+0000] {taskinstance.py:3313} ERROR - Task failed with exception
Traceback (most recent call last):
  File "/home/airflow/.local/lib/python3.8/site-packages/airflow/models/taskinstance.py", line 768, in _execute_task
    result = _execute_callable(context=context, **execute_callable_kwargs)
  File "/home/airflow/.local/lib/python3.8/site-packages/airflow/models/taskinstance.py", line 734, in _execute_callable
    return ExecutionCallableRunner(
  File "/home/airflow/.local/lib/python3.8/site-packages/airflow/utils/operator_helpers.py", line 252, in run
    return self.func(*args, **kwargs)
  File "/home/airflow/.local/lib/python3.8/site-packages/airflow/models/baseoperator.py", line 424, in wrapper
    return func(self, *args, **kwargs)
  File "/home/airflow/.local/lib/python3.8/site-packages/airflow/operators/bash.py", line 276, in execute
    raise AirflowException(
airflow.exceptions.AirflowException: Bash command failed. The command returned a non-zero exit code 255.
[2025-04-18T08:04:53.403+0000] {taskinstance.py:1226} INFO - Marking task as FAILED. dag_id=ssh_to_host_from_config, task_id=execute_remote_script_on_host, run_id=manual__2025-04-18T08:04:52.210566+00:00, execution_date=20250418T080452, start_date=20250418T080452, end_date=20250418T080453
[2025-04-18T08:04:53.428+0000] {taskinstance.py:341} INFO - ::group::Post task execution logs
[2025-04-18T08:04:53.428+0000] {standard_task_runner.py:124} ERROR - Failed to execute job 327 for task execute_remote_script_on_host (Bash command failed. The command returned a non-zero exit code 255.; 204)
Traceback (most recent call last):
  File "/home/airflow/.local/lib/python3.8/site-packages/airflow/task/task_runner/standard_task_runner.py", line 117, in _start_by_fork
    ret = args.func(args, dag=self.dag)
  File "/home/airflow/.local/lib/python3.8/site-packages/airflow/cli/cli_config.py", line 49, in command
    return func(*args, **kwargs)
  File "/home/airflow/.local/lib/python3.8/site-packages/airflow/utils/cli.py", line 116, in wrapper
    return f(*args, **kwargs)
  File "/home/airflow/.local/lib/python3.8/site-packages/airflow/cli/commands/task_command.py", line 483, in task_run
    task_return_code = _run_task_by_selected_method(args, _dag, ti)
  File "/home/airflow/.local/lib/python3.8/site-packages/airflow/cli/commands/task_command.py", line 256, in _run_task_by_selected_method
    return _run_raw_task(args, ti)
  File "/home/airflow/.local/lib/python3.8/site-packages/airflow/cli/commands/task_command.py", line 341, in _run_raw_task
    return ti._run_raw_task(
  File "/home/airflow/.local/lib/python3.8/site-packages/airflow/utils/session.py", line 97, in wrapper
    return func(*args, session=session, **kwargs)
  File "/home/airflow/.local/lib/python3.8/site-packages/airflow/models/taskinstance.py", line 3006, in _run_raw_task
    return _run_raw_task(
  File "/home/airflow/.local/lib/python3.8/site-packages/airflow/models/taskinstance.py", line 274, in _run_raw_task
    TaskInstance._execute_task_with_callbacks(
  File "/home/airflow/.local/lib/python3.8/site-packages/airflow/models/taskinstance.py", line 3161, in _execute_task_with_callbacks
    result = self._execute_task(context, task_orig)
  File "/home/airflow/.local/lib/python3.8/site-packages/airflow/models/taskinstance.py", line 3185, in _execute_task
    return _execute_task(self, context, task_orig)
  File "/home/airflow/.local/lib/python3.8/site-packages/airflow/models/taskinstance.py", line 768, in _execute_task
    result = _execute_callable(context=context, **execute_callable_kwargs)
  File "/home/airflow/.local/lib/python3.8/site-packages/airflow/models/taskinstance.py", line 734, in _execute_callable
    return ExecutionCallableRunner(
  File "/home/airflow/.local/lib/python3.8/site-packages/airflow/utils/operator_helpers.py", line 252, in run
    return self.func(*args, **kwargs)
  File "/home/airflow/.local/lib/python3.8/site-packages/airflow/models/baseoperator.py", line 424, in wrapper
    return func(self, *args, **kwargs)
  File "/home/airflow/.local/lib/python3.8/site-packages/airflow/operators/bash.py", line 276, in execute
    raise AirflowException(
airflow.exceptions.AirflowException: Bash command failed. The command returned a non-zero exit code 255.
[2025-04-18T08:04:53.456+0000] {local_task_job_runner.py:266} INFO - Task exited with return code 1
[2025-04-18T08:04:53.471+0000] {taskinstance.py:3901} INFO - 0 downstream tasks scheduled from follow-on schedule check
[2025-04-18T08:04:53.474+0000] {local_task_job_runner.py:245} INFO - ::endgroup::
